Traceback (most recent call last):
  File "/usr/local/lib/python3.7/dist-packages/jupyter_cache/executors/utils.py", line 56, in single_nb_execution
    record_timing=False,
  File "/usr/local/lib/python3.7/dist-packages/nbclient/client.py", line 1204, in execute
    return NotebookClient(nb=nb, resources=resources, km=km, **kwargs).execute()
  File "/usr/local/lib/python3.7/dist-packages/nbclient/util.py", line 84, in wrapped
    return just_run(coro(*args, **kwargs))
  File "/usr/local/lib/python3.7/dist-packages/nbclient/util.py", line 62, in just_run
    return loop.run_until_complete(coro)
  File "/usr/lib/python3.7/asyncio/base_events.py", line 587, in run_until_complete
    return future.result()
  File "/usr/local/lib/python3.7/dist-packages/nbclient/client.py", line 664, in async_execute
    cell, index, execution_count=self.code_cells_executed + 1
  File "/usr/local/lib/python3.7/dist-packages/nbclient/client.py", line 965, in async_execute_cell
    await self._check_raise_for_error(cell, cell_index, exec_reply)
  File "/usr/local/lib/python3.7/dist-packages/nbclient/client.py", line 862, in _check_raise_for_error
    raise CellExecutionError.from_cell_and_msg(cell, exec_reply_content)
nbclient.exceptions.CellExecutionError: An error occurred while executing the following cell:
------------------
from sklearn.datasets import df
x,y = df(return_X_y=True)

print(f'Dimensi Feature: {X.shape}')
print(f'Class: {set(y)}')
------------------

[0;31m[0m
[0;31mImportError[0mTraceback (most recent call last)
[0;32m<ipython-input-4-b4374a4f104b>[0m in [0;36m<module>[0;34m[0m
[0;32m----> 1[0;31m [0;32mfrom[0m [0msklearn[0m[0;34m.[0m[0mdatasets[0m [0;32mimport[0m [0mdf[0m[0;34m[0m[0;34m[0m[0m
[0m[1;32m      2[0m [0mx[0m[0;34m,[0m[0my[0m [0;34m=[0m [0mdf[0m[0;34m([0m[0mreturn_X_y[0m[0;34m=[0m[0;32mTrue[0m[0;34m)[0m[0;34m[0m[0;34m[0m[0m
[1;32m      3[0m [0;34m[0m[0m
[1;32m      4[0m [0mprint[0m[0;34m([0m[0;34mf'Dimensi Feature: {X.shape}'[0m[0;34m)[0m[0;34m[0m[0;34m[0m[0m
[1;32m      5[0m [0mprint[0m[0;34m([0m[0;34mf'Class: {set(y)}'[0m[0;34m)[0m[0;34m[0m[0;34m[0m[0m

[0;31mImportError[0m: cannot import name 'df' from 'sklearn.datasets' (/usr/local/lib/python3.7/dist-packages/sklearn/datasets/__init__.py)

[0;31m---------------------------------------------------------------------------[0;32m
NOTE: If your import is failing due to a missing package, you can
manually install dependencies using either !pip or !apt.

To view examples of installing some common dependencies, click the
"Open Examples" button below.
[0;31m---------------------------------------------------------------------------[0m

ImportError: cannot import name 'df' from 'sklearn.datasets' (/usr/local/lib/python3.7/dist-packages/sklearn/datasets/__init__.py)

